2019-09-28 15:55:13,589 ERROR: Exception on /index [GET] [in /Users/mrerico/Desktop/climb_dest/venv/lib/python3.7/site-packages/flask/app.py:1761]
Traceback (most recent call last):
  File "/Users/mrerico/Desktop/climb_dest/venv/lib/python3.7/site-packages/flask/app.py", line 2292, in wsgi_app
    response = self.full_dispatch_request()
  File "/Users/mrerico/Desktop/climb_dest/venv/lib/python3.7/site-packages/flask/app.py", line 1815, in full_dispatch_request
    rv = self.handle_user_exception(e)
  File "/Users/mrerico/Desktop/climb_dest/venv/lib/python3.7/site-packages/flask/app.py", line 1718, in handle_user_exception
    reraise(exc_type, exc_value, tb)
  File "/Users/mrerico/Desktop/climb_dest/venv/lib/python3.7/site-packages/flask/_compat.py", line 35, in reraise
    raise value
  File "/Users/mrerico/Desktop/climb_dest/venv/lib/python3.7/site-packages/flask/app.py", line 1813, in full_dispatch_request
    rv = self.dispatch_request()
  File "/Users/mrerico/Desktop/climb_dest/venv/lib/python3.7/site-packages/flask/app.py", line 1799, in dispatch_request
    return self.view_functions[rule.endpoint](**req.view_args)
  File "/Users/mrerico/Desktop/climb_dest/app/main/routes.py", line 151, in index
    currency_form=currency_form, user=User)
  File "/Users/mrerico/Desktop/climb_dest/venv/lib/python3.7/site-packages/flask/templating.py", line 135, in render_template
    context, ctx.app)
  File "/Users/mrerico/Desktop/climb_dest/venv/lib/python3.7/site-packages/flask/templating.py", line 117, in _render
    rv = template.render(context)
  File "/Users/mrerico/Desktop/climb_dest/venv/lib/python3.7/site-packages/jinja2/asyncsupport.py", line 76, in render
    return original_render(self, *args, **kwargs)
  File "/Users/mrerico/Desktop/climb_dest/venv/lib/python3.7/site-packages/jinja2/environment.py", line 1008, in render
    return self.environment.handle_exception(exc_info, True)
  File "/Users/mrerico/Desktop/climb_dest/venv/lib/python3.7/site-packages/jinja2/environment.py", line 780, in handle_exception
    reraise(exc_type, exc_value, tb)
  File "/Users/mrerico/Desktop/climb_dest/venv/lib/python3.7/site-packages/jinja2/_compat.py", line 37, in reraise
    raise value.with_traceback(tb)
  File "/Users/mrerico/Desktop/climb_dest/app/templates/index.html", line 1, in top-level template code
    {% extends "base.html" %}
  File "/Users/mrerico/Desktop/climb_dest/app/templates/base.html", line 36, in top-level template code
    <a href="{{ url_for('index') }}"><img src="{{ url_for('static', filename='images/climb_dest_6.svg') }}"
  File "/Users/mrerico/Desktop/climb_dest/venv/lib/python3.7/site-packages/flask/helpers.py", line 356, in url_for
    return appctx.app.handle_url_build_error(error, endpoint, values)
  File "/Users/mrerico/Desktop/climb_dest/venv/lib/python3.7/site-packages/flask/app.py", line 2061, in handle_url_build_error
    reraise(exc_type, exc_value, tb)
  File "/Users/mrerico/Desktop/climb_dest/venv/lib/python3.7/site-packages/flask/_compat.py", line 35, in reraise
    raise value
  File "/Users/mrerico/Desktop/climb_dest/venv/lib/python3.7/site-packages/flask/helpers.py", line 345, in url_for
    force_external=external)
  File "/Users/mrerico/Desktop/climb_dest/venv/lib/python3.7/site-packages/werkzeug/routing.py", line 1776, in build
    raise BuildError(endpoint, values, method, self)
werkzeug.routing.BuildError: Could not build url for endpoint 'index'. Did you mean 'main.index' instead?
2019-09-28 15:55:14,559 ERROR: Exception on /index [GET] [in /Users/mrerico/Desktop/climb_dest/venv/lib/python3.7/site-packages/flask/app.py:1761]
Traceback (most recent call last):
  File "/Users/mrerico/Desktop/climb_dest/venv/lib/python3.7/site-packages/flask/app.py", line 2292, in wsgi_app
    response = self.full_dispatch_request()
  File "/Users/mrerico/Desktop/climb_dest/venv/lib/python3.7/site-packages/flask/app.py", line 1815, in full_dispatch_request
    rv = self.handle_user_exception(e)
  File "/Users/mrerico/Desktop/climb_dest/venv/lib/python3.7/site-packages/flask/app.py", line 1718, in handle_user_exception
    reraise(exc_type, exc_value, tb)
  File "/Users/mrerico/Desktop/climb_dest/venv/lib/python3.7/site-packages/flask/_compat.py", line 35, in reraise
    raise value
  File "/Users/mrerico/Desktop/climb_dest/venv/lib/python3.7/site-packages/flask/app.py", line 1813, in full_dispatch_request
    rv = self.dispatch_request()
  File "/Users/mrerico/Desktop/climb_dest/venv/lib/python3.7/site-packages/flask/app.py", line 1799, in dispatch_request
    return self.view_functions[rule.endpoint](**req.view_args)
  File "/Users/mrerico/Desktop/climb_dest/app/main/routes.py", line 151, in index
    currency_form=currency_form, user=User)
  File "/Users/mrerico/Desktop/climb_dest/venv/lib/python3.7/site-packages/flask/templating.py", line 135, in render_template
    context, ctx.app)
  File "/Users/mrerico/Desktop/climb_dest/venv/lib/python3.7/site-packages/flask/templating.py", line 117, in _render
    rv = template.render(context)
  File "/Users/mrerico/Desktop/climb_dest/venv/lib/python3.7/site-packages/jinja2/asyncsupport.py", line 76, in render
    return original_render(self, *args, **kwargs)
  File "/Users/mrerico/Desktop/climb_dest/venv/lib/python3.7/site-packages/jinja2/environment.py", line 1008, in render
    return self.environment.handle_exception(exc_info, True)
  File "/Users/mrerico/Desktop/climb_dest/venv/lib/python3.7/site-packages/jinja2/environment.py", line 780, in handle_exception
    reraise(exc_type, exc_value, tb)
  File "/Users/mrerico/Desktop/climb_dest/venv/lib/python3.7/site-packages/jinja2/_compat.py", line 37, in reraise
    raise value.with_traceback(tb)
  File "/Users/mrerico/Desktop/climb_dest/app/templates/index.html", line 1, in top-level template code
    {% extends "base.html" %}
  File "/Users/mrerico/Desktop/climb_dest/app/templates/base.html", line 36, in top-level template code
    <a href="{{ url_for('index') }}"><img src="{{ url_for('static', filename='images/climb_dest_6.svg') }}"
  File "/Users/mrerico/Desktop/climb_dest/venv/lib/python3.7/site-packages/flask/helpers.py", line 356, in url_for
    return appctx.app.handle_url_build_error(error, endpoint, values)
  File "/Users/mrerico/Desktop/climb_dest/venv/lib/python3.7/site-packages/flask/app.py", line 2061, in handle_url_build_error
    reraise(exc_type, exc_value, tb)
  File "/Users/mrerico/Desktop/climb_dest/venv/lib/python3.7/site-packages/flask/_compat.py", line 35, in reraise
    raise value
  File "/Users/mrerico/Desktop/climb_dest/venv/lib/python3.7/site-packages/flask/helpers.py", line 345, in url_for
    force_external=external)
  File "/Users/mrerico/Desktop/climb_dest/venv/lib/python3.7/site-packages/werkzeug/routing.py", line 1776, in build
    raise BuildError(endpoint, values, method, self)
werkzeug.routing.BuildError: Could not build url for endpoint 'index'. Did you mean 'main.index' instead?
2019-09-29 08:56:08,506 INFO: Climbit startup [in /Users/mrerico/Desktop/climb_dest/app/__init__.py:57]
2019-10-12 16:56:19,706 INFO: Climbit startup [in /Users/mrerico/Desktop/climb_dest/app/__init__.py:85]
2019-10-12 17:06:38,959 INFO: Climbit startup [in /Users/mrerico/Desktop/climb_dest/app/__init__.py:85]
2019-10-13 07:42:15,338 INFO: Climbit startup [in /Users/mrerico/Desktop/climb_dest/app/__init__.py:85]
2019-10-13 07:57:19,565 INFO: Climbit startup [in /Users/mrerico/Desktop/climb_dest/app/__init__.py:85]
2019-11-02 10:44:24,078 INFO: Climbit startup [in /Users/mrerico/Desktop/climb_dest/app/__init__.py:85]
2019-11-02 10:45:02,488 INFO: Climbit startup [in /Users/mrerico/Desktop/climb_dest/app/__init__.py:85]
2019-11-02 10:48:15,751 INFO: Climbit startup [in /Users/mrerico/Desktop/climb_dest/app/__init__.py:85]
2019-11-02 10:50:54,417 ERROR: Exception on /add_destination [POST] [in /Users/mrerico/Desktop/climb_dest/venv/lib/python3.7/site-packages/flask/app.py:1761]
Traceback (most recent call last):
  File "/Users/mrerico/Desktop/climb_dest/venv/lib/python3.7/site-packages/flask/app.py", line 2292, in wsgi_app
    response = self.full_dispatch_request()
  File "/Users/mrerico/Desktop/climb_dest/venv/lib/python3.7/site-packages/flask/app.py", line 1815, in full_dispatch_request
    rv = self.handle_user_exception(e)
  File "/Users/mrerico/Desktop/climb_dest/venv/lib/python3.7/site-packages/flask/app.py", line 1718, in handle_user_exception
    reraise(exc_type, exc_value, tb)
  File "/Users/mrerico/Desktop/climb_dest/venv/lib/python3.7/site-packages/flask/_compat.py", line 35, in reraise
    raise value
  File "/Users/mrerico/Desktop/climb_dest/venv/lib/python3.7/site-packages/flask/app.py", line 1813, in full_dispatch_request
    rv = self.dispatch_request()
  File "/Users/mrerico/Desktop/climb_dest/venv/lib/python3.7/site-packages/flask/app.py", line 1799, in dispatch_request
    return self.view_functions[rule.endpoint](**req.view_args)
  File "/Users/mrerico/Desktop/climb_dest/venv/lib/python3.7/site-packages/flask_login/utils.py", line 261, in decorated_view
    return func(*args, **kwargs)
  File "/Users/mrerico/Desktop/climb_dest/app/destinations/routes.py", line 36, in add_destination
    if save_destination(form, d, new=True):
NameError: name 'd' is not defined
2019-11-02 10:51:34,900 INFO: Climbit startup [in /Users/mrerico/Desktop/climb_dest/app/__init__.py:85]
